Workbook

Sheet GERAL
A1: DATA | B1: OPERAÇÃO | C1: SSS (R$) | D1: SSO (UN) | E1: ADT (MIN) | F1: EXTREMO (UN) | G1: ENTREGAS/MOTOBOY | H1: CMV | I1: LOCALIZAÇÃO
A2: 45257 | B2: CAMPO BELO | D2: 32 | E2: 20,9 | I2: Sao Paulo
A3: 45257 | B3: JABAQUARA | C3: 3673.26 | D3: 49 | E3: 24,9 | I3: Sao Paulo
A4: 45257 | B4: JARDIM CAMBURI | C4: 1970.56 | D4: 25 | E4: 28,7 | I4: Espirito Santo
A5: 45257 | B5: PRAIA DO CANTO | C5: 2142.4 | D5: 30 | E5: 30,3 | I5: Espirito Santo
A6: 45257 | B6: SERRA | C6: 2591.52 | D6: 32 | E6: 31,8 | I6: Espirito Santo
A7: 45257 | B7: VILA CLEMENTINO | C7: 4245.18 | D7: 48 | E7: 22 | I7: Sao Paulo
A8: 45258 | B8: CAMPO BELO | D8: 59 | E8: 26,8 | I8: Sao Paulo
A9: 45258 | B9: JABAQUARA | C9: 3606.78 | D9: 43 | E9: 23,6 | I9: Sao Paulo
A10: 45258 | B10: JARDIM CAMBURI | C10: 3003.15 | D10: 38 | E10: 24,8 | I10: Espirito Santo
A11: 45258 | B11: PRAIA DO CANTO | C11: 2907.1 | D11: 30 | E11: 28,4 | I11: Espirito Santo
A12: 45258 | B12: SERRA | C12: 3504.1 | D12: 38 | E12: 22,5 | I12: Espirito Santo
A13: 45258 | B13: VILA CLEMENTINO | C13: 6902.63 | D13: 75 | E13: 23,7 | I13: Sao Paulo
A14: 45259 | B14: CAMPO BELO | C14: 3713.54 | D14: 48 | E14: 22,5 | I14: Sao Paulo
A15: 45259 | B15: JABAQUARA | C15: 4049.47 | D15: 51 | E15: 22,9 | I15: Sao Paulo
A16: 45259 | B16: JARDIM CAMBURI | C16: 3021.96 | D16: 39 | E16: 37,9 | I16: Espirito Santo
A17: 45259 | B17: PRAIA DO CANTO | C17: 4638.78 | D17: 50 | E17: 48,4 | I17: Espirito Santo
A18: 45259 | B18: SERRA | C18: 2123.03 | D18: 25 | E18: 25,2 | I18: Espirito Santo
A19: 45259 | B19: VILA CLEMENTINO | C19: 4272.19 | D19: 51 | E19: 23,4 | I19: Sao Paulo
A20: 45260 | B20: CAMPO BELO | C20: 7013.71 | D20: 74 | E20: 29,4 | I20: Sao Paulo
... A25: 45260 | B25: VILA CLEMENTINO | C25: 5238.82 | D25: 63 | E25: 22,4 | I25: Sao Paulo
A26: 45261 | B26: VILA CLEMENTINO | C26: 8661.82 | D26: 103 | E26: 22,7 | H26: 0.265 | I26: Sao Paulo
A27: 45261 | B27: CAMPO BELO | C27: 8561.52 | D27: 100 | E27: 25,3 | H27: 0.277 | I27: Sao Paulo
A28: 45261 | B28: JABAQUARA | C28: 5745.61 | D28: 71 | E28: 24,3 | H28: 0.3 | I28: Sao Paulo
A29: 45261 | B29: VILA GOPOUVA | C29: 5395.68 | D29: 63 | E29: 21,9 | H29: 0.317 | I29: Sao Paulo
A30: 45261 | B30: PARQUE MANDAQUI | C30: 6264.32 | D30: 66 | E30: 24,2 | H30: 0.333 | I30: Sao Paulo
A31: 45261 | B31: JARDIM CAMBURI | C31: 6240.71 | D31: 74 | E31: 33,8 | I31: Espirito Santo
A32: 45261 | B32: PRAIA DO CANTO | C32: 7998.97 | D32: 84 | E32: 30,4 | I32: Espirito Santo
A33: 45261 | B33: SERRA | C33: 5385.33 | D33: 57 | E33: 27,1 | I33: Espirito Santo
A34: 45262 | B34: VILA GOPOUVA | C34: 5850.22 | D34: 62 | E34: 20,3 | H34: 0.263 | I34: Sao Paulo
A35: 45262 | B35: CAMPO BELO | C35: 9764 | D35: 115 | E35: 21,7 | H35: 0.274 | I35: Sao Paulo
A36: 45262 | B36: PARQUE MANDAQUI | C36: 6999.99 | D36: 73 | E36: 29,3 | H36: 0.284 | I36: Sao Paulo
A37: 45262 | B37: VILA CLEMENTINO | C37: 12575.1 | D37: 100 | E37: 23,9 | H37: 0.295 | I37: Sao Paulo
A38: 45262 | B38: JABAQUARA | C38: 7571.15 | D38: 83 | E38: 23,4 | H38: 0.305 | I38: Sao Paulo
A39: 45262 | B39: JARDIM CAMBURI | C39: 7001.66 | D39: 82 | E39: 31,7 | I39: Espirito Santo
A40: 45262 | B40: PRAIA DO CANTO | C40: 7072.81 | D40: 81 | E40: 28,9 | I40: Espirito Santo
A41: 45262 | B41: SERRA | C41: 7547.24 | D41: 86 | E41: 31,2 | I41: Espirito Santo
A42: 45263 | B42: CAMPO BELO | C42: 6909.23 | D42: 87 | E42: 20,5 | H42: 0.269 | I42: Sao Paulo
A43: 45263 | B43: VILA CLEMENTINO | C43: 9523.89 | D43: 111 | E43: 24 | H43: 0.273 | I43: Sao Paulo
A44: 45263 | B44: PARQUE MANDAQUI | C44: 6643.32 | D44: 78 | E44: 28 | H44: 0.305 | I44: Sao Paulo
...

Sheet FATURAMENTO
A1: DATA | B1: LOJA | C1: FAT | D1: TC | F1: TOTAL | G1: TC | H1: TM
A2: 46139 | B2: JARDIM CAMBURI | C2: 1447.2 | D2: 17
A3: 46140 | B3: JARDIM CAMBURI | C3: 3375.89 | D3: 30
A4: 46141 | B4: JARDIM CAMBURI | C4: 3038 | D4: 34
A5: 46142 | B5: JARDIM CAMBURI | C5: 6321.51 | D5: 67
A7: 46143 | B7: JARDIM CAMBURI | C7: 6382.85 | D7: 67
A8: 46144 | B8: JARDIM CAMBURI | C8: 6635.55 | D8: 76
A9: 46145 | B9: JARDIM CAMBURI | C9: 6797.56 | D9: 78
F10: =SUM(C2:C9) -> 33998.56 | G10: =SUM(D2:D9) -> 369 | H10: =F10/G10 -> 92.137019
A11: 46139 | B11: SPOLETO JABAQUARA | C11: 3720.14 | D11: 74
A12: 46140 | B12: SPOLETO JABAQUARA | C12: 3483.18 | D12: 65
A13: 46141 | B13: SPOLETO JABAQUARA | C13: 1211.99 | D13: 21
A14: 46142 | B14: SPOLETO JABAQUARA | C14: 4025.36 | D14: 78
A15: 46143 | B15: SPOLETO JABAQUARA | C15: 3567.98 | D15: 67
A16: 46144 | B16: SPOLETO JABAQUARA | C16: 3810.73 | D16: 68
A17: 46145 | B17: SPOLETO JABAQUARA | C17: 3505.67 | D17: 66
F18: =SUM(C10:C17) -> 23325.05 | G18: =SUM(D10:D17) -> 439 | H18: =F18/G18 -> 53.132232
A19: 46139 | B19: VILA CLEMENTINO | C19: 4905.25 | D19: 51
A20: 46140 | B20: VILA CLEMENTINO | C20: 5300.45 | D20: 60
A21: 46141 | B21: VILA CLEMENTINO | C21: 4782.21 | D21: 57
A22: 46142 | B22: VILA CLEMENTINO | C22: 9600 | D22: 100
A23: 46143 | B23: VILA CLEMENTINO | C23: 9510.95 | D23: 96
A24: 46144 | B24: VILA CLEMENTINO | C24: 9653.51 | D24: 98
A25: 46145 | B25: VILA CLEMENTINO | C25: 9308.77 | D25: 105
F26: =SUM(C18:C25) -> 53061.14 | G26: =SUM(D18:D25) -> 567 | H26: =F26/G26 -> 93.582257
A27: 46139 | B27: BOALI | C27: 3014.3 | D27: 81
A28: 46140 | B28: BOALI | C28: 3571.61 | D28: 82
A29: 46141 | B29: BOALI | C29: 3842.56 | D29: 96
A30: 46142 | B30: BOALI | C30: 3576.63 | D30: 88
A31: 46143 | B31: BOALI | C31: 2799.69 | D31: 72
A32: 46144 | B32: BOALI | C32: 2691.6 | D32: 72
A33: 46145 | B33: BOALI | C33: 3561.78 | D33: 95
F34: =SUM(C26:C33) -> 23058.17 | G34: =SUM(D26:D33) -> 586 | H34: =F34/G34 -> 39.348413

Sheet BOALI
B1: OPERAÇÃO | C1: SSS (R$) | D1: SSO (UN) | E1: ADT (MIN) | F1: EXTREMO (UN) | G1: ENTREGAS/MOTOBOY | H1: CMV | I1: LOCALIZAÇÃO
A2: 46023 | B2: BOALI | I2: Espirito Santo
A3: 46024 | B3: BOALI | C3: 3013.74 | D3: 67 | I3: Espirito Santo
A4: 46025 | B4: BOALI | C4: 2561.6 | D4: 59 | I4: Espirito Santo
A5: 46026 | B5: BOALI | C5: 3218.62 | D5: 66 | I5: Espirito Santo
A6: 46027 | B6: BOALI | C6: 4282.43 | D6: 93 | I6: Espirito Santo
A7: 46028 | B7: BOALI | C7: 3884.38 | D7: 94 | I7: Espirito Santo
A8: 46029 | B8: BOALI | C8: 3695.4 | D8: 85 | I8: Espirito Santo
A9: 46030 | B9: BOALI | C9: 4728.57 | D9: 116 | I9: Espirito Santo
A10: 46031 | B10: BOALI | C10: 3239.01 | D10: 77 | I10: Espirito Santo
A11: 46032 | B11: BOALI | C11: 2750.42 | D11: 67 | I11: Espirito Santo
A12: 46033 | B12: BOALI | C12: 2599.14 | D12: 47 | I12: Espirito Santo
A13: 46034 | B13: BOALI | C13: 4748.49 | D13: 104 | I13: Espirito Santo
A14: 46035 | B14: BOALI | C14: 3468.61 | D14: 89 | I14: Espirito Santo
... A166: 46187 | B166: BOALI | C166: 2846.74 | D166: 87 | I166: Espirito Santo
A167: 46188 | B167: BOALI | I167: Espirito Santo
A168: 46189 | B168: BOALI | I168: Espirito Santo
A169: 46190 | B169: BOALI | I169: Espirito Santo
A170: 46191 | B170: BOALI | I170: Espirito Santo
A171: 46192 | B171: BOALI | I171: Espirito Santo
A172: 46193 | B172: BOALI | I172: Espirito Santo
A173: 46194 | B173: BOALI | I173: Espirito Santo
A174: 46195 | B174: BOALI | I174: Espirito Santo
A175: 46196 | B175: BOALI | I175: Espirito Santo
A176: 46197 | B176: BOALI | I176: Espirito Santo
A177: 46198 | B177: BOALI | I177: Espirito Santo
A178: 46199 | B178: BOALI | I178: Espirito Santo
... A183: 46204 | B183: BOALI | I183: Espirito Santo
I184: Espirito Santo
I185: Espirito Santo
I186: Espirito Santo
I187: Espirito Santo
I188: Espirito Santo
I189: Espirito Santo
I190: Espirito Santo
I191: Espirito Santo
I192: Espirito Santo
I193: Espirito Santo
I194: Espirito Santo
I195: Espirito Santo
...

Sheet SERRA
A1: 29.1 | B1: OPERAÇÃO | C1: SSS (R$) | D1: SSO (UN) | E1: ADT (MIN) | F1: EXTREMO (UN) | G1: ENTREGAS/MOTOBOY | H1: CMV | I1: LOCALIZAÇÃO | K1: NOME | L1: DATA | M1: DIA SEMANA | N1: S/ TX ENTREGA | O1: C/ TX ENTREGA | P1: TC | Q1: TM | R1: DATA | S1: DIA SEMANA | T1: FAT ORÇADO | U1: REALIZADO | V1: TM | W1: DIF | X1: TC ORÇADO | Y1: REALIZADO | Z1: VAR | AA1: BASE | AB1: 1.1
A2: 45998 | B2: SERRA | C2: 5987.08 | D2: 70 | E2: 35.76 | F2: 8 | G2: 5.8 | H2: 0.2876 | I2: Espirito Santo
A3: 45999 | B3: SERRA | C3: 3772.84 | D3: 13 | E3: 36.47 | F3: 4 | G3: 6.5 | H3: 0.271 | I3: Espirito Santo
A4: 46000 | B4: SERRA | C4: 2448.3 | D4: 11 | E4: 21.1 | F4: 0 | G4: 3.6 | H4: 0.2617 | I4: Espirito Santo
A5: 46001 | B5: SERRA | C5: 3434.23 | D5: 19 | E5: 29.46 | F5: 0 | G5: 6.33 | H5: 0.2929 | I5: Espirito Santo
A6: 46002 | B6: SERRA | C6: 2845.64 | D6: 17 | E6: 25.47 | F6: 1 | G6: 5.66 | H6: 0.3136 | I6: Espirito Santo
A7: 46003 | B7: SERRA | C7: 3953.48 | D7: 17 | E7: 26.3 | F7: 0 | G7: 3.4 | H7: 0.304 | I7: Espirito Santo
A8: 46004 | B8: SERRA | C8: 5863.06 | D8: 33 | E8: 25.55 | F8: 0 | G8: 5.25 | H8: 0.3208 | I8: Espirito Santo
A9: 46005 | B9: SERRA | C9: 7129.89 | D9: 45 | E9: 36.5 | F9: 16 | G9: 11.25 | H9: 0.2992 | I9: Espirito Santo
A10: 46006 | B10: SERRA | C10: 3446.34 | D10: 12 | E10: 38.5 | F10: 4 | G10: 6 | H10: 0.3266 | I10: Espirito Santo
A11: 46007 | B11: SERRA | C11: 3746.64 | D11: 18 | E11: 28.83 | F11: 0 | G11: 6 | H11: 0.3316 | I11: Espirito Santo
A12: 46008 | B12: SERRA | C12: 3703.55 | D12: 45 | E12: 37.11 | F12: 7 | G12: 15 | H12: 0.3126 | I12: Espirito Santo
A13: 46009 | B13: SERRA | C13: 2617 | D13: 24 | E13: 35.51 | F13: 4 | G13: 8 | H13: 0.3394 | I13: Espirito Santo
... A18: 46014 | B18: SERRA | C18: 5028.73 | D18: 29 | E18: 38.43 | F18: 15 | G18: 9.6 | H18: 0.3566 | I18: Espirito Santo
A19: 46015 | B19: SERRA | I19: Espirito Santo | J19: FECHADA
A20: 46016 | B20: SERRA | C20: 6323.32 | D20: 63 | E20: 25.07 | F20: 0 | G20: 15.75 | H20: 0.266 | I20: Espirito Santo
A21: 46017 | B21: SERRA | C21: 3107.08 | D21: 18 | E21: 27.69 | F21: 2 | G21: 4.5 | H21: 0.2786 | I21: Espirito Santo
A22: 46018 | B22: SERRA | C22: 7034.6 | D22: 71 | E22: 39.12 | F22: 16 | G22: 17.75 | H22: 0.3299 | I22: Espirito Santo
A23: 46019 | B23: SERRA | C23: 7482.91 | D23: 76 | E23: 38.06 | F23: 16 | G23: 25.3 | H23: 0.319 | I23: Espirito Santo
A24: 46020 | B24: SERRA | C24: 3150.38 | D24: 35 | E24: 57 | F24: 15 | G24: 17.5 | H24: 0.3408 | I24: Espirito Santo
A25: 46021 | B25: SERRA | C25: 6939.6 | D25: 33 | E25: 31.94 | F25: 9 | G25: 11 | H25: 0.2896 | I25: Espirito Santo
A26: 46022 | B26: SERRA | I26: Espirito Santo | J26: FECHADA | K26: NOME | L26: DATA | N26: S/ TX ENTREGA | O26: C/ TX ENTREGA | P26: TC | Q26: TM | R26: DATA | T26: FAT ORÇADO | U26: REALIZADO | V26: TM | W26: DIF | X26: TC ORÇADO | Y26: REALIZADO | Z26: VAR | AA26: BASE | AB26: 1.1
A27: 46023 | B27: SERRA | C27: 7543.56 | D27: 73 | E27: 45.08 | F27: 16 | G27: 18.25 | H27: 0.3288 | I27: Espirito Santo | K27: SERRA | L27: 45658 | M27: 45658 | N27: 9795.08 | O27: 10370.18 | P27: 103 | Q27: =O27/P27 -> 100.68136 | R27: 46023 | S27: 46023 | T27: =O28*$AB$26 -> 4120.028 | U27: =C27 -> 7543.56 | V27: =U27/Y27 -> 103.33644 | W27: =U27-T27 -> 3423.532 | X27: =P27*$AB$1 -> 113.3 | Y27: =D27 -> 73 | Z27: =Y27-X27 -> -40.3
A28: 46024 | B28: SERRA | C28: 4047.5 | D28: 44 | E28: 42.09 | F28: 6 | G28: 8.8 | H28: 0.3212 | I28: Espirito Santo | K28: SERRA | L28: 45659 | M28: 45659 | N28: 3560.88 | O28: 3745.48 | P28: 38 | Q28: =O28/P28 -> 98.565263 | R28: 46024 | S28: 46024 | T28: =O29*$AB$26 -> 5502.519 | U28: =C28 -> 4047.5 | V28: =U28/Y28 -> 91.988636 | W28: =U28-T28 -> -1455.019 | X28: =P28*$AB$1 -> 41.8 | Y28: =D28 -> 44 | Z28: =Y28-X28 -> 2.2
A29: 46025 | B29: SERRA | C29: 6096.48 | D29: 73 | E29: 25.35 | F29: 1 | G29: 18.25 | H29: 0.336 | I29: Espirito Santo | K29: SERRA | L29: 45660 | M29: 45660 | N29: 4817.69 | O29: 5002.29 | P29: 56 | Q29: =O29/P29 -> 89.326607 | R29: 46025 | S29: 46025 | T29: =O30*$AB$26 -> 7962.526 | U29: =C29 -> 6096.48 | V29: =U29/Y29 -> 83.513425 | W29: =U29-T29 -> -1866.046 | X29: =P29*$AB$1 -> 61.6 | Y29: =D29 -> 73 | Z29: =Y29-X29 -> 11.4
A30: 46026 | B30: SERRA | C30: 7555.93 | D30: 94 | E30: 34.99 | F30: 13 | G30: 31.33 | H30: 0.337 | I30: Espirito Santo | K30: SERRA | L30: 45661 | M30: 45661 | N30: 6968.86 | O30: 7238.66 | P30: 74 | Q30: =O30/P30 -> 97.81973 | R30: 46026 | S30: 46026 | T30: =O31*$AB$26 -> 9566.964 | U30: =C30 -> 7555.93 | V30: =U30/Y30 -> 80.382234 | W30: =U30-T30 -> -2011.034 | X30: =P30*$AB$1 -> 81.4 | Y30: =D30 -> 94 | Z30: =Y30-X30 -> 12.6
A31: 46027 | B31: SERRA | C31: 4047.86 | D31: 44 | E31: 41.74 | F31: 8 | G31: 22 | H31: 0.3533 | I31: Espirito Santo | K31: SERRA | L31: 45662 | M31: 45662 | N31: 8370.64 | O31: 8697.24 | P31: 97 | Q31: =O31/P31 -> 89.662268 | R31: 46027 | S31: 46027 | T31: =O32*$AB$26 -> 4132.26 | U31: =C31 -> 4047.86 | V31: =U31/Y31 -> 91.996818 | W31: =U31-T31 -> -84.4 | X31: =P31*$AB$1 -> 106.7 | Y31: =D31 -> 44 | Z31: =Y31-X31 -> -62.7
A32: 46028 | B32: SERRA | C32: 2275.88 | D32: 13 | E32: 33.98 | F32: 3 | G32: 4.33 | H32: 0.3554 | I32: Espirito Santo | K32: SERRA | L32: 45663 | M32: 45663 | N32: 3572 | O32: 3756.6 | P32: 33 | Q32: =O32/P32 -> 113.83636 | R32: 46028 | S32: 46028 | T32: =O33*$AB$26 -> 6429.808 | U32: =C32 -> 2275.88 | V32: =U32/Y32 -> 175.06769 | W32: =U32-T32 -> -4153.928 | X32: =P32*$AB$1 -> 36.3 | Y32: =D32 -> 13 | Z32: =Y32-X32 -> -23.3
A33: 46029 | B33: SERRA | C33: 2764.96 | D33: 16 | E33: 20.35 | F33: 0 | G33: 5.3 | H33: 0.3152 | I33: Espirito Santo | K33: SERRA | L33: 45664 | M33: 45664 | N33: 5518.68 | O33: 5845.28 | P33: 57 | Q33: =O33/P33 -> 102.54877 | R33: 46029 | S33: 46029 | T33: =O34*$AB$26 -> 5508.096 | U33: =C33 -> 2764.96 | V33: =U33/Y33 -> 172.81 | W33: =U33-T33 -> -2743.136 | X33: =P33*$AB$1 -> 62.7 | Y33: =D33 -> 16 | Z33: =Y33-X33 -> -46.7
A34: 46030 | B34: SERRA | C34: 3271.9 | D34: 33 | E34: 23.24 | F34: 0 | G34: 11 | H34: 0.3053 | I34: Espirito Santo | K34: SERRA | L34: 45665 | M34: 45665 | N34: 4815.66 | O34: 5007.36 | P34: 69 | Q34: =O34/P34 -> 72.570435 | R34: 46030 | S34: 46030 | T34: =O35*$AB$26 -> 5983.967 | U34: =C34 -> 3271.9 | V34: =U34/Y34 -> 99.148485 | W34: =U34-T34 -> -2712.067 | X34: =P34*$AB$1 -> 75.9 | Y34: =D34 -> 33 | Z34: =Y34-X34 -> -42.9
A35: 46031 | B35: SERRA | C35: 5340.93 | D35: 52 | E35: 34.12 | F35: 8 | G35: 13 | H35: 0.3079 | I35: Espirito Santo | K35: SERRA | L35: 45666 | M35: 45666 | N35: 5305.07 | O35: 5439.97 | P35: 54 | Q35: =O35/P35 -> 100.74019 | R35: 46031 | S35: 46031 | T35: =O36*$AB$26 -> 7750.765 | U35: =C35 -> 5340.93 | V35: =U35/Y35 -> 102.71019 | W35: =U35-T35 -> -2409.835 | X35: =P35*$AB$1 -> 59.4 | Y35: =D35 -> 52 | Z35: =Y35-X35 -> -7.4
A36: 46032 | B36: SERRA | C36: 4146.7 | D36: 47 | E36: 29.13 | F36: 3 | G36: 11.75 | H36: 0.3381 | I36: Espirito Santo | K36: SERRA | L36: 45667 | M36: 45667 | N36: 6747.95 | O36: 7046.15 | P36: 82 | Q36: =O36/P36 -> 85.928659 | R36: 46032 | S36: 46032 | T36: =O37*$AB$26 -> 9261.769 | U36: =C36 -> 4146.7 | V36: =U36/Y36 -> 88.22766 | W36: =U36-T36 -> -5115.069 | X36: =P36*$AB$1 -> 90.2 | Y36: =D36 -> 47 | Z36: =Y36-X36 -> -43.2
A37: 46033 | B37: SERRA | C37: 7940.01 | D37: 79 | E37: 35.68 | F37: 7 | G37: 12.33 | H37: 0.3075 | I37: Espirito Santo | K37: SERRA | L37: 45668 | M37: 45668 | N37: 8043.49 | O37: 8419.79 | P37: 104 | Q37: =O37/P37 -> 80.959519 | R37: 46033 | S37: 46033 | T37: =O38*$AB$26 -> 8329.904 | U37: =C37 -> 7940.01 | V37: =U37/Y37 -> 100.50646 | W37: =U37-T37 -> -389.894 | X37: =P37*$AB$1 -> 114.4 | Y37: =D37 -> 79 | Z37: =Y37-X37 -> -35.4
A38: 46034 | B38: SERRA | C38: 1852.23 | D38: 20 | E38: 23.12 | F38: 0 | G38: 10 | H38: 0.3351 | I38: Espirito Santo | K38: SERRA | L38: 45669 | M38: 45669 | N38: 7217.64 | O38: 7572.64 | P38: 95 | Q38: =O38/P38 -> 79.712 | R38: 46034 | S38: 46034 | T38: =O39*$AB$26 -> 3408.955 | U38: =C38 -> 1852.23 | V38: =U38/Y38 -> 92.6115 | W38: =U38-T38 -> -1556.725 | X38: =P38*$AB$1 -> 104.5 | Y38: =D38 -> 20 | Z38: =Y38-X38 -> -84.5
... A49: 46045 | B49: SERRA | C49: 4516.8 | D49: 43 | E49: 26.13 | F49: 1 | G49: 8.6 | H49: 0.2772 | I49: Espirito Santo | K49: SERRA | L49: 45680 | M49: 45680 | N49: 3470.13 | O49: 3633.43 | P49: 44 | Q49: =O49/P49 -> 82.577955 | R49: 46045 | S49: 46045 | T49: =O50*$AB$26 -> 6730.9 | U49: =C49 -> 4516.8 | V49: =U49/Y49 -> 105.04186 | W49: =U49-T49 -> -2214.1 | X49: =P49*$AB$1 -> 48.4 | Y49: =D49 -> 43 | Z49: =Y49-X49 -> -5.4
A50: 46046 | B50: SERRA | C50: 5785.5 | D50: 29 | E50: 29.26 | F50: 4 | G50: 9.66 | H50: 0.3617 | I50: Espirito Santo | J50: TRABALHARAM SEM SISTEMA | K50: SERRA | L50: 45681 | M50: 45681 | N50: 5849.2 | O50: 6119 | P50: 65 | Q50: =O50/P50 -> 94.138462 | R50: 46046 | S50: 46046 | T50: =O51*$AB$26 -> 9086.055 | U50: =C50 -> 5785.5 | V50: =U50/Y50 -> 199.5 | W50: =U50-T50 -> -3300.555 | X50: =P50*$AB$1 -> 71.5 | Y50: =D50 -> 29 | Z50: =Y50-X50 -> -42.5
A51: 46047 | B51: SERRA | C51: 6414.19 | D51: 86 | E51: 33.6 | F51: 4 | G51: 17.2 | H51: 0.2841 | I51: Espirito Santo | K51: SERRA | L51: 45682 | M51: 45682 | N51: 7954.75 | O51: 8260.05 | P51: 84 | Q51: =O51/P51 -> 98.333929 | R51: 46047 | S51: 46047 | T51: =O52*$AB$26 -> 10021.473 | U51: =C51 -> 6414.19 | V51: =U51/Y51 -> 74.583605 | W51: =U51-T51 -> -3607.283 | X51: =P51*$AB$1 -> 92.4 | Y51: =D51 -> 86 | Z51: =Y51-X51 -> -6.4
A52: 46048 | B52: SERRA | C52: 2235.94 | D52: 24 | E52: 34.83 | F52: 4 | G52: 12 | H52: 0.2931 | I52: Espirito Santo | K52: SERRA | L52: 45683 | M52: 45683 | N52: 8741.23 | O52: 9110.43 | P52: 102 | Q52: =O52/P52 -> 89.317941 | R52: 46048 | S52: 46048 | T52: =O53*$AB$26 -> 3039.817 | U52: =C52 -> 2235.94 | V52: =U52/Y52 -> 93.164167 | W52: =U52-T52 -> -803.877 | X52: =P52*$AB$1 -> 112.2 | Y52: =D52 -> 24 | Z52: =Y52-X52 -> -88.2
A53: 46049 | B53: SERRA | C53: 3692.63 | D53: 44 | E53: 31.96 | F53: 4 | G53: 22 | H53: 0.248 | I53: Espirito Santo | K53: SERRA | L53: 45684 | M53: 45684 | N53: 2578.87 | O53: 2763.47 | P53: 37 | Q53: =O53/P53 -> 74.688378 | R53: 46049 | S53: 46049 | T53: =O54*$AB$26 -> 4080.483 | U53: =C53 -> 3692.63 | V53: =U53/Y53 -> 83.923409 | W53: =U53-T53 -> -387.853 | X53: =P53*$AB$1 -> 40.7 | Y53: =D53 -> 44 | Z53: =Y53-X53 -> 3.3
A54: 46050 | B54: SERRA | C54: 3537.02 | D54: 37 | E54: 24.89 | F54: 1 | G54: 12.33 | H54: 0.2959 | I54: Espirito Santo | K54: SERRA | L54: 45685 | M54: 45685 | N54: 3574.63 | O54: 3709.53 | P54: 46 | Q54: =O54/P54 -> 80.641957 | R54: 46050 | S54: 46050 | T54: =O55*$AB$26 -> 4024.812 | U54: =C54 -> 3537.02 | V54: =U54/Y54 -> 95.595135 | W54: =U54-T54 -> -487.792 | X54: =P54*$AB$1 -> 50.6 | Y54: =D54 -> 37 | Z54: =Y54-X54 -> -13.6
...

Sheet JARDIM CAMBURI
B1: OPERAÇÃO | C1: SSS (R$) | D1: SSO (UN) | E1: ADT (MIN) | F1: EXTREMO (UN) | G1: ENTREGAS/MOTOBOY | H1: CMV | I1: LOCALIZAÇÃO | J1: OBS | K1: DATA | L1: DIA SEMANA | M1: S/ TX ENTREGA | N1: C/ TX ENTREGA | O1: TC | P1: TM | Q1: DATA | R1: DIA SEMANA | S1: FAT ORÇADO | T1: REALIZADO | U1: TM | V1: DIF | W1: TC ORÇADO | X1: REALIZADO | Y1: VAR | Z1: CRESCIMENTO | AA1: 1.1
A2: 45998 | B2: JARDIM CAMBURI | C2: 9283.18 | D2: 109 | E2: 39.17 | F2: 33 | G2: 16.2 | H2: 0.325 | I2: Espirito Santo
A3: 45999 | B3: JARDIM CAMBURI | C3: 2532.12 | D3: 16 | E3: 24.5 | F3: 0 | G3: 5.3 | H3: 0.2349 | I3: Espirito Santo
A4: 46000 | B4: JARDIM CAMBURI | C4: 5025.38 | D4: 31 | E4: 35.84 | F4: 8 | G4: 3.8 | H4: 0.3667 | I4: Espirito Santo
A5: 46001 | B5: JARDIM CAMBURI | C5: 4271 | D5: 33 | E5: 22.4 | F5: 1 | G5: 11 | H5: 0.2656 | I5: Espirito Santo
A6: 46002 | B6: JARDIM CAMBURI | C6: 3209.8 | D6: 21 | E6: 31.97 | F6: 1 | G6: 7 | H6: 0.2866 | I6: Espirito Santo
A7: 46003 | B7: JARDIM CAMBURI | C7: 6608.64 | D7: 51 | E7: 25.13 | F7: 0 | G7: 7 | H7: 0.1909 | I7: Espirito Santo
A8: 46004 | B8: JARDIM CAMBURI | C8: 8005.64 | D8: 67 | E8: 21.9 | F8: 0 | G8: 5 | H8: 0.248 | I8: Espirito Santo
A9: 46005 | B9: JARDIM CAMBURI | C9: 8361.14 | D9: 70 | E9: 22.99 | F9: 0 | H9: 0.2711 | I9: Espirito Santo
A10: 46006 | B10: JARDIM CAMBURI | C10: 2884.02 | D10: 23 | E10: 22.93 | F10: 0 | G10: 7.6 | H10: 0.2493 | I10: Espirito Santo
A11: 46007 | B11: JARDIM CAMBURI | C11: 4570.4 | D11: 37 | E11: 25.32 | F11: 0 | G11: 9 | H11: 0.27 | I11: Espirito Santo
A12: 46008 | B12: JARDIM CAMBURI | C12: 5883.76 | D12: 43 | E12: 30.21 | F12: 6 | G12: 21.5 | H12: 0.2195 | I12: Espirito Santo
A13: 46009 | B13: JARDIM CAMBURI | C13: 4630.88 | D13: 34 | E13: 24.22 | F13: 0 | G13: 11.33 | H13: 0.2004 | I13: Espirito Santo
A14: 46010 | B14: JARDIM CAMBURI | C14: 6095.54 | D14: 43 | E14: 44.26 | F14: 26 | G14: 7.16 | H14: 0.1983 | I14: Espirito Santo
A15: 46011 | B15: JARDIM CAMBURI | C15: 8513.69 | D15: 58 | E15: 42.17 | F15: 32 | G15: 9.66 | H15: 0.2667 | I15: Espirito Santo
A16: 46012 | B16: JARDIM CAMBURI | C16: 9305.84 | D16: 76 | E16: 45.21 | F16: 49 | G16: 15.2 | H16: 0.2832 | I16: Espirito Santo
A17: 46013 | B17: JARDIM CAMBURI | C17: 4625.08 | D17: 27 | E17: 30.43 | F17: 27 | G17: 13.5 | H17: 0.293 | I17: Espirito Santo
A18: 46014 | B18: JARDIM CAMBURI | C18: 7124.7 | D18: 53 | E18: 37.15 | F18: 21 | G18: 13.25 | H18: 0.2571 | I18: Espirito Santo
A19: 46015 | B19: JARDIM CAMBURI | I19: Espirito Santo | J19: FECHADA
A20: 46016 | B20: JARDIM CAMBURI | C20: 11014.04 | D20: 73 | E20: 38.9 | F20: 35 | G20: 12.16 | H20: 0.285 | I20: Espirito Santo
A21: 46017 | B21: JARDIM CAMBURI | C21: 5828.34 | D21: 41 | E21: 32.5 | F21: 7 | G21: 6.83 | H21: 0.253 | I21: Espirito Santo
A22: 46018 | B22: JARDIM CAMBURI | C22: 7283.94 | D22: 55 | E22: 32.19 | F22: 10 | G22: 11 | H22: 0.263 | I22: Espirito Santo
A23: 46019 | B23: JARDIM CAMBURI | C23: 8494.5 | D23: 69 | E23: 45.66 | F23: 49 | G23: 17.25 | H23: 0.2612 | I23: Espirito Santo
A24: 46020 | B24: JARDIM CAMBURI | C24: 5349.29 | D24: 50 | E24: 38 | F24: 4 | G24: 12.6 | H24: 0.2566 | I24: Espirito Santo
A25: 46021 | B25: JARDIM CAMBURI | C25: 9064.13 | D25: 85 | E25: 62 | F25: 30 | G25: 20.6 | H25: 0.2371 | I25: Espirito Santo
A26: 46022 | B26: JARDIM CAMBURI | I26: Espirito Santo | J26: FECHADA | K26: DATA | M26: S/ TX ENTREGA | N26: C/ TX ENTREGA | O26: TC | P26: TM | Q26: DATA | S26: FAT ORÇADO | T26: REALIZADO | U26: TM | V26: DIF | W26: TC ORÇADO | X26: REALIZADO | Y26: VAR
A27: 46023 | B27: JARDIM CAMBURI | C27: 11857.08 | D27: 118 | E27: 44.64 | F27: 50 | G27: 16.2 | H27: 0.235 | I27: Espirito Santo | K27: 45658 | L27: =K27 -> 45658 | M27: 13526.48 | N27: 14009.48 | O27: 148 | P27: =N27/O27 -> 94.658649 | Q27: 46023 | R27: =Q27 -> 46023 | S27: =N28*$AA$1 -> 6269.362 | T27: =C27 -> 11857.08 | U27: =T27/X27 -> 100.48373 | V27: =T27-S27 -> 5587.718 | W27: =O27*$AA$1 -> 162.8 | X27: =D27 -> 118 | Y27: =X27-W27 -> -44.8
A28: 46024 | B28: JARDIM CAMBURI | C28: 6300.62 | D28: 61 | E28: 18.26 | F28: 0 | G28: 9.8 | H28: 0.1955 | I28: Espirito Santo | K28: 45659 | L28: =K28 -> 45659 | M28: 5423.42 | N28: 5699.42 | O28: 57 | P28: =N28/O28 -> 99.989825 | Q28: 46024 | R28: =Q28 -> 46024 | S28: =N29*$AA$1 -> 7911.387 | T28: =C28 -> 6300.62 | U28: =T28/X28 -> 103.28885 | V28: =T28-S28 -> -1610.767 | W28: =O28*$AA$1 -> 62.7 | X28: =D28 -> 61 | Y28: =X28-W28 -> -1.7
A29: 46025 | B29: JARDIM CAMBURI | C29: 8678.8 | D29: 83 | E29: 28.27 | F29: 6 | G29: 15.75 | H29: 0.1938 | I29: Espirito Santo | K29: 45660 | L29: =K29 -> 45660 | M29: 6805.77 | N29: 7192.17 | O29: 86 | P29: =N29/O29 -> 83.629884 | Q29: 46025 | R29: =Q29 -> 46025 | S29: =N30*$AA$1 -> 6375.765 | T29: =C29 -> 8678.8 | U29: =T29/X29 -> 104.56386 | V29: =T29-S29 -> 2303.035 | W29: =O29*$AA$1 -> 94.6 | X29: =D29 -> 83 | Y29: =X29-W29 -> -11.6
A30: 46026 | B30: JARDIM CAMBURI | C30: 9619.7 | D30: 109 | E30: 48.25 | F30: 50 | G30: 17.75 | H30: 0.1985 | I30: Espirito Santo | K30: 45661 | L30: =K30 -> 45661 | M30: 5458.05 | N30: 5796.15 | O30: 75 | P30: =N30/O30 -> 77.282 | Q30: 46026 | R30: =Q30 -> 46026 | S30: =N31*$AA$1 -> 11055.429 | T30: =C30 -> 9619.7 | U30: =T30/X30 -> 88.254128 | V30: =T30-S30 -> -1435.729 | W30: =O30*$AA$1 -> 82.5 | X30: =D30 -> 109 | Y30: =X30-W30 -> 26.5
A31: 46027 | B31: JARDIM CAMBURI | C31: 6317.58 | D31: 64 | E31: 26.09 | F31: 2 | G31: 14.66 | H31: 0.2335 | I31: Espirito Santo | K31: 45662 | L31: =K31 -> 45662 | M31: 9505.29 | N31: 10050.39 | O31: 113 | P31: =N31/O31 -> 88.941504 | Q31: 46027 | R31: =Q31 -> 46027 | S31: =N32*$AA$1 -> 6934.169 | T31: =C31 -> 6317.58 | U31: =T31/X31 -> 98.712187 | V31: =T31-S31 -> -616.589 | W31: =O31*$AA$1 -> 124.3 | X31: =D31 -> 64 | Y31: =X31-W31 -> -60.3
A32: 46028 | B32: JARDIM CAMBURI | C32: 3743.66 | D32: 39 | E32: 22.44 | F32: 0 | G32: 8.66 | H32: 0.224 | I32: Espirito Santo | K32: 45663 | L32: =K32 -> 45663 | M32: 6124.39 | N32: 6303.79 | O32: 68 | P32: =N32/O32 -> 92.702794 | Q32: 46028 | R32: =Q32 -> 46028 | S32: =N33*$AA$1 -> 7889.068 | T32: =C32 -> 3743.66 | U32: =T32/X32 -> 95.991282 | V32: =T32-S32 -> -4145.408 | W32: =O32*$AA$1 -> 74.8 | X32: =D32 -> 39 | Y32: =X32-W32 -> -35.8
A33: 46029 | B33: JARDIM CAMBURI | C33: 4715.04 | D33: 43 | E33: 33.72 | F33: 4 | G33: 14.33 | H33: 0.3292 | I33: Espirito Santo | K33: 45664 | L33: =K33 -> 45664 | M33: 6840.68 | N33: 7171.88 | O33: 80 | P33: =N33/O33 -> 89.6485 | Q33: 46029 | R33: =Q33 -> 46029 | S33: =N34*$AA$1 -> 4411.11 | T33: =C33 -> 4715.04 | U33: =T33/X33 -> 109.65209 | V33: =T33-S33 -> 303.93 | W33: =O33*$AA$1 -> 88 | X33: =D33 -> 43 | Y33: =X33-W33 -> -45
A34: 46030 | B34: JARDIM CAMBURI | C34: 4664.38 | D34: 53 | E34: 22.63 | F34: 0 | G34: 13.66 | H34: 0.2532 | I34: Espirito Santo | K34: 45665 | L34: =K34 -> 45665 | M34: 3872.1 | N34: 4010.1 | O34: 51 | P34: =N34/O34 -> 78.629412 | Q34: 46030 | R34: =Q34 -> 46030 | S34: =N35*$AA$1 -> 6273.531 | T34: =C34 -> 4664.38 | U34: =T34/X34 -> 88.00717 | V34: =T34-S34 -> -1609.151 | W34: =O34*$AA$1 -> 56.1 | X34: =D34 -> 53 | Y34: =X34-W34 -> -3.1
A35: 46031 | B35: JARDIM CAMBURI | C35: 6018.23 | D35: 65 | E35: 26.8 | F35: 1 | G35: 8.33 | H35: 0.2807 | I35: Espirito Santo | K35: 45666 | L35: =K35 -> 45666 | M35: 5496.21 | N35: 5703.21 | O35: 65 | P35: =N35/O35 -> 87.741692 | Q35: 46031 | R35: =Q35 -> 46031 | S35: =N36*$AA$1 -> 8632.415 | T35: =C35 -> 6018.23 | U35: =T35/X35 -> 92.588154 | V35: =T35-S35 -> -2614.185 | W35: =O35*$AA$1 -> 71.5 | X35: =D35 -> 65 | Y35: =X35-W35 -> -6.5
A36: 46032 | B36: JARDIM CAMBURI | C36: 5960.7 | D36: 69 | E36: 31.8 | F36: 1 | G36: 9.2 | H36: 0.3193 | I36: Espirito Santo | K36: 45667 | L36: =K36 -> 45667 | M36: 7468.15 | N36: 7847.65 | O36: 77 | P36: =N36/O36 -> 101.91753 | Q36: 46032 | R36: =Q36 -> 46032 | S36: =N37*$AA$1 -> 7580.188 | T36: =C36 -> 5960.7 | U36: =T36/X36 -> 86.386957 | V36: =T36-S36 -> -1619.488 | W36: =O36*$AA$1 -> 84.7 | X36: =D36 -> 69 | Y36: =X36-W36 -> -15.7
A37: 46033 | B37: JARDIM CAMBURI | C37: 8625.74 | D37: 102 | E37: 28.69 | F37: 6 | G37: 15.75 | H37: 0.2915 | I37: Espirito Santo | K37: 45668 | L37: =K37 -> 45668 | M37: 6656.48 | N37: 6891.08 | O37: 80 | P37: =N37/O37 -> 86.1385 | Q37: 46033 | R37: =Q37 -> 46033 | S37: =N38*$AA$1 -> 8863.107 | T37: =C37 -> 8625.74 | U37: =T37/X37 -> 84.566078 | V37: =T37-S37 -> -237.367 | W37: =O37*$AA$1 -> 88 | X37: =D37 -> 102 | Y37: =X37-W37 -> 14
A38: 46034 | B38: JARDIM CAMBURI | C38: 3037.8 | D38: 31 | E38: 13.35 | F38: 0 | G38: 6.33 | H38: 0.2986 | I38: Espirito Santo | K38: 45669 | L38: =K38 -> 45669 | M38: 7767.57 | N38: 8057.37 | O38: 96 | P38: =N38/O38 -> 83.930937 | Q38: 46034 | R38: =Q38 -> 46034 | S38: =N39*$AA$1 -> 4119.94 | T38: =C38 -> 3037.8 | U38: =T38/X38 -> 97.993548 | V38: =T38-S38 -> -1082.14 | W38: =O38*$AA$1 -> 105.6 | X38: =D38 -> 31 | Y38: =X38-W38 -> -74.6
... A56: 46052 | B56: JARDIM CAMBURI | C56: 9426.49 | D56: 100 | E56: 31.76 | F56: 8 | G56: 13.6 | H56: 0.21 | I56: Espirito Santo | K56: 45687 | L56: =K56 -> 45687 | M56: 4632.64 | N56: 4756.84 | O56: 59 | P56: =N56/O56 -> 80.624407 | Q56: 46052 | R56: =Q56 -> 46052 | S56: =N57*$AA$1 -> 8252.816 | T56: =C56 -> 9426.49 | U56: =T56/X56 -> 94.2649 | V56: =T56-S56 -> 1173.674 | W56: =O56*$AA$1 -> 64.9 | X56: =D56 -> 100 | Y56: =X56-W56 -> 35.1
A57: 46053 | B57: JARDIM CAMBURI | C57: 8011.3 | D57: 86 | E57: 35.03 | F57: 3 | G57: 13 | H57: 0.2731 | I57: Espirito Santo | K57: 45688 | L57: =K57 -> 45688 | M57: 7288.66 | N57: 7502.56 | O57: 84 | P57: =N57/O57 -> 89.31619 | Q57: 46053 | R57: =Q57 -> 46053 | S57: =N59*$AA$1 -> 8945.145 | T57: =C57 -> 8011.3 | U57: =T57/X57 -> 93.154651 | V57: =T57-S57 -> -933.845 | W57: =O57*$AA$1 -> 92.4 | X57: =D57 -> 86 | Y57: =X57-W57 -> -6.4
...

Sheet PRAIA DO CANTO
B1: OPERAÇÃO | C1: SSS (R$) | D1: SSO (UN) | E1: ADT (MIN) | F1: EXTREMO (UN) | G1: ENTREGAS/MOTOBOY | H1: CMV | I1: LOCALIZAÇÃO | J1: OBS | K1: NOME | L1: DATA | M1: DIA DA SEMANA | N1: S/ TX ENTREGA | O1: C/ TX ENTREGA | P1: TC | Q1: TM | R1: DATA | S1: DIA DA SEMANA | T1: ORÇADO FAT | U1: REALIZADO | V1: TM | W1: DIF | X1: ORÇADO TC | Y1: REALIZADO | Z1: VAR | AA1: 1.1
A2: 45998 | B2: PRAIA DO CANTO | C2: 12184.34 | D2: 138 | E2: 28.48 | F2: 3 | G2: 17.66 | H2: 0.3057 | I2: Espirito Santo | K2: UNIDADE | N2: VALOR LIQUIDO | R2: PERÍODO: 01/01/2026 À: 30/06/2026 | AA2: 1.1
A3: 45999 | B3: PRAIA DO CANTO | C3: 4818.34 | D3: 33 | E3: 22.52 | F3: 1 | G3: 11 | H3: 0.2884 | I3: Espirito Santo
A4: 46000 | B4: PRAIA DO CANTO | C4: 7202.19 | D4: 51 | E4: 25.63 | F4: 0 | G4: 10.2 | H4: 0.3317 | I4: Espirito Santo
A5: 46001 | B5: PRAIA DO CANTO | C5: 5210.24 | D5: 47 | E5: 24.04 | F5: 0 | G5: 9.4 | H5: 0.2966 | I5: Espirito Santo
A6: 46002 | B6: PRAIA DO CANTO | C6: 5275.71 | D6: 37 | E6: 29.55 | F6: 10 | G6: 9.25 | H6: 0.272 | I6: Espirito Santo
A7: 46003 | B7: PRAIA DO CANTO | C7: 11202.47 | D7: 98 | E7: 23.91 | F7: 9 | G7: 14 | H7: 0.298 | I7: Espirito Santo
A8: 46004 | B8: PRAIA DO CANTO | C8: 8853.18 | D8: 78 | E8: 24.74 | F8: 0 | G8: 15.6 | H8: 0.3176 | I8: Espirito Santo
A9: 46005 | B9: PRAIA DO CANTO | C9: 12298.05 | D9: 102 | E9: 33.06 | F9: 18 | G9: 20.4 | H9: 0.3129 | I9: Espirito Santo
A10: 46006 | B10: PRAIA DO CANTO | C10: 5196.74 | D10: 44 | E10: 31.58 | F10: 4 | G10: 14.66 | H10: 0.2661 | I10: Espirito Santo
A11: 46007 | B11: PRAIA DO CANTO | C11: 7170.72 | D11: 54 | E11: 43.32 | F11: 27 | G11: 10.8 | H11: 0.3356 | I11: Espirito Santo
A12: 46008 | B12: PRAIA DO CANTO | C12: 9070.2 | D12: 63 | E12: 36.07 | F12: 25 | G12: 15.75 | H12: 0.2922 | I12: Espirito Santo
A13: 46009 | B13: PRAIA DO CANTO | C13: 4363.49 | D13: 37 | E13: 24.59 | F13: 2 | G13: 9.25 | H13: 0.3128 | I13: Espirito Santo
A14: 46010 | B14: PRAIA DO CANTO | C14: 9031.12 | D14: 76 | E14: 29.92 | F14: 12 | G14: 15.2 | H14: 0.3125 | I14: Espirito Santo
... A18: 46014 | B18: PRAIA DO CANTO | C18: 11735.08 | D18: 77 | E18: 62.37 | F18: 57 | G18: 15.4 | H18: 0.333 | I18: Espirito Santo
A19: 46015 | B19: PRAIA DO CANTO | I19: Espirito Santo | J19: FECHADA
A20: 46016 | B20: PRAIA DO CANTO | C20: 10919.76 | D20: 81 | E20: 30.08 | F20: 5 | G20: 16.2 | H20: 0.3099 | I20: Espirito Santo
A21: 46017 | B21: PRAIA DO CANTO | C21: 7167.9 | D21: 55 | E21: 21.6 | F21: 0 | G21: 9.16 | H21: 0.2971 | I21: Espirito Santo
A22: 46018 | B22: PRAIA DO CANTO | C22: 6083.06 | D22: 55 | E22: 23.06 | F22: 1 | G22: 9.16 | H22: 0.3113 | I22: Espirito Santo
A23: 46019 | B23: PRAIA DO CANTO | C23: 9820.48 | D23: 80 | E23: 21.66 | F23: 0 | G23: 13.33 | H23: 0.2934 | I23: Espirito Santo
A24: 46020 | B24: PRAIA DO CANTO | C24: 6518.03 | D24: 41 | E24: 19.84 | F24: 0 | G24: 13.66 | H24: 0.3075 | I24: Espirito Santo | K24: PERÍODO: 01/01/2025 À: 30/06/2025 | AA24: BASE
A25: 46021 | B25: PRAIA DO CANTO | C25: 8743.38 | D25: 60 | E25: 31.23 | F25: 12 | G25: 15 | H25: 0.3242 | I25: Espirito Santo | K25: UNIDADE | L25: DATA | N25: VALOR LIQUIDO | P25: TC | Q25: TM | R25: PERÍODO: 01/01/2026 À: 30/06/2026 | AA25: 1.1
A26: 46022 | B26: PRAIA DO CANTO | I26: Espirito Santo | J26: FECHADA | K26: NOME | N26: S/ TX ENTREGA | O26: C/ TX ENTREGA | R26: DATA | T26: ORÇADO FAT | U26: REALIZADO | V26: TM | W26: DIF | X26: ORÇADO TC | Y26: REALIZADO | Z26: VAR
A27: 46023 | B27: PRAIA DO CANTO | C27: 13241.37 | D27: 134 | E27: 35.81 | F27: 19 | G27: 24.25 | H27: 0.313 | I27: Espirito Santo | K27: PRAIA DO CANTO | L27: 45658 | M27: =L27 -> 45658 | N27: 16847.01 | O27: 17676.61 | P27: 164 | Q27: =O27/P27 -> 107.78421 | R27: =L27+365 -> 46023 | S27: =R27 -> 46023 | T27: =O28*$AA$1 -> 5662.162 | U27: =C27 -> 13241.37 | V27: =U27/Y27 -> 98.816194 | W27: =U27-T27 -> 7579.208 | X27: =P27*$AA$25 -> 180.4 | Y27: =D27 -> 134 | Z27: =Y27-X27 -> -46.4
A28: 46024 | B28: PRAIA DO CANTO | C28: 6816.34 | D28: 68 | E28: 25.13 | F28: 2 | G28: 8.33 | H28: 0.271 | I28: Espirito Santo | K28: PRAIA DO CANTO | L28: 45659 | M28: =L28 -> 45659 | N28: 4879.02 | O28: 5147.42 | P28: 56 | Q28: =O28/P28 -> 91.918214 | R28: =L28+365 -> 46024 | S28: =R28 -> 46024 | T28: =O29*$AA$1 -> 7899.551 | U28: =C28 -> 6816.34 | V28: =U28/Y28 -> 100.24029 | W28: =U28-T28 -> -1083.211 | X28: =P28*$AA$25 -> 61.6 | Y28: =D28 -> 68 | Z28: =Y28-X28 -> 6.4
A29: 46025 | B29: PRAIA DO CANTO | C29: 8527.81 | D29: 88 | E29: 25.26 | F29: 0 | G29: 18 | H29: 0.2963 | I29: Espirito Santo | K29: PRAIA DO CANTO | L29: 45660 | M29: =L29 -> 45660 | N29: 6803.21 | O29: 7181.41 | P29: 75 | Q29: =O29/P29 -> 95.752133 | R29: 46025 | S29: =R29 -> 46025 | T29: =O30*$AA$1 -> 7678.825 | U29: =C29 -> 8527.81 | V29: =U29/Y29 -> 96.906932 | W29: =U29-T29 -> 848.985 | X29: =P29*$AA$25 -> 82.5 | Y29: =D29 -> 88 | Z29: =Y29-X29 -> 5.5
A30: 46026 | B30: PRAIA DO CANTO | C30: 12894.29 | D30: 138 | E30: 31.34 | F30: 20 | G30: 20.8 | H30: 0.3047 | I30: Espirito Santo | K30: PRAIA DO CANTO | L30: 45661 | M30: =L30 -> 45661 | N30: 6614.75 | O30: 6980.75 | P30: 71 | Q30: =O30/P30 -> 98.320423 | R30: 46026 | S30: =R30 -> 46026 | T30: =O31*$AA$1 -> 11947.166 | U30: =C30 -> 12894.29 | V30: =U30/Y30 -> 93.436884 | W30: =U30-T30 -> 947.124 | X30: =P30*$AA$25 -> 78.1 | Y30: =D30 -> 138 | Z30: =Y30-X30 -> 59.9
A31: 46027 | B31: PRAIA DO CANTO | C31: 7116.91 | D31: 73 | E31: 31.47 | F31: 10 | G31: 19 | H31: 0.3062 | I31: Espirito Santo | K31: PRAIA DO CANTO | L31: 45662 | M31: =L31 -> 45662 | N31: 10318.16 | O31: 10861.06 | P31: 114 | Q31: =O31/P31 -> 95.272456 | R31: 46027 | S31: =R31 -> 46027 | T31: =O32*$AA$1 -> 7181.834 | U31: =C31 -> 7116.91 | V31: =U31/Y31 -> 97.491918 | W31: =U31-T31 -> -64.924 | X31: =P31*$AA$25 -> 125.4 | Y31: =D31 -> 73 | Z31: =Y31-X31 -> -52.4
A32: 46028 | B32: PRAIA DO CANTO | C32: 7768.58 | D32: 71 | E32: 29.64 | F32: 8 | G32: 11.75 | H32: 0.3628 | I32: Espirito Santo | K32: PRAIA DO CANTO | L32: 45663 | M32: =L32 -> 45663 | N32: 6309.34 | O32: 6528.94 | P32: 63 | Q32: =O32/P32 -> 103.63397 | R32: 46028 | S32: =R32 -> 46028 | T32: =O33*$AA$1 -> 7462.312 | U32: =C32 -> 7768.58 | V32: =U32/Y32 -> 109.41662 | W32: =U32-T32 -> 306.268 | X32: =P32*$AA$25 -> 69.3 | Y32: =D32 -> 71 | Z32: =Y32-X32 -> 1.7
A33: 46029 | B33: PRAIA DO CANTO | C33: 5739.69 | D33: 66 | E33: 34.43 | F33: 13 | G33: 10.75 | H33: 0.3136 | I33: Espirito Santo | K33: PRAIA DO CANTO | L33: 45664 | M33: =L33 -> 45664 | N33: 6478.92 | O33: 6783.92 | P33: 71 | Q33: =O33/P33 -> 95.548169 | R33: 46029 | S33: =R33 -> 46029 | T33: =O34*$AA$1 -> 7124.337 | U33: =C33 -> 5739.69 | V33: =U33/Y33 -> 86.965 | W33: =U33-T33 -> -1384.647 | X33: =P33*$AA$25 -> 78.1 | Y33: =D33 -> 66 | Z33: =Y33-X33 -> -12.1
A34: 46030 | B34: PRAIA DO CANTO | C34: 4505.81 | D34: 47 | E34: 26.51 | F34: 4 | G34: 9.6 | H34: 0.3341 | I34: Espirito Santo | K34: PRAIA DO CANTO | L34: 45665 | M34: =L34 -> 45665 | N34: 6135.07 | O34: 6476.67 | P34: 68 | Q34: =O34/P34 -> 95.245147 | R34: 46030 | S34: =R34 -> 46030 | T34: =O35*$AA$1 -> 6166.017 | U34: =C34 -> 4505.81 | V34: =U34/Y34 -> 95.868298 | W34: =U34-T34 -> -1660.207 | X34: =P34*$AA$25 -> 74.8 | Y34: =D34 -> 47 | Z34: =Y34-X34 -> -27.8
A35: 46031 | B35: PRAIA DO CANTO | C35: 10864.98 | D35: 90 | E35: 27.47 | F35: 3 | G35: 14.2 | H35: 0.3159 | I35: Espirito Santo | K35: PRAIA DO CANTO | L35: 45666 | M35: =L35 -> 45666 | N35: 5288.27 | O35: 5605.47 | P35: 64 | Q35: =O35/P35 -> 87.585469 | R35: 46031 | S35: =R35 -> 46031 | T35: =O36*$AA$1 -> 5581.587 | U35: =C35 -> 10864.98 | V35: =U35/Y35 -> 120.722 | W35: =U35-T35 -> 5283.393 | X35: =P35*$AA$25 -> 70.4 | Y35: =D35 -> 90 | Z35: =Y35-X35 -> 19.6
A36: 46032 | B36: PRAIA DO CANTO | C36: 9065.58 | D36: 92 | E36: 26.5 | F36: 5 | G36: 14.2 | H36: 0.317 | I36: Espirito Santo | K36: PRAIA DO CANTO | L36: 45667 | M36: =L36 -> 45667 | N36: 4842.37 | O36: 5074.17 | P36: 50 | Q36: =O36/P36 -> 101.4834 | R36: 46032 | S36: =R36 -> 46032 | T36: =O37*$AA$1 -> 6829.515 | U36: =C36 -> 9065.58 | V36: =U36/Y36 -> 98.538913 | W36: =U36-T36 -> 2236.065 | X36: =P36*$AA$25 -> 55 | Y36: =D36 -> 92 | Z36: =Y36-X36 -> 37
A37: 46033 | B37: PRAIA DO CANTO | C37: 11415.44 | D37: 116 | E37: 26.32 | F37: 3 | G37: 22 | H37: 0.2933 | I37: Espirito Santo | K37: PRAIA DO CANTO | L37: 45668 | M37: =L37 -> 45668 | N37: 5915.85 | O37: 6208.65 | P37: 63 | Q37: =O37/P37 -> 98.55 | R37: 46033 | S37: =R37 -> 46033 | T37: =O38*$AA$1 -> 12224.685 | U37: =C37 -> 11415.44 | V37: =U37/Y37 -> 98.408966 | W37: =U37-T37 -> -809.245 | X37: =P37*$AA$25 -> 69.3 | Y37: =D37 -> 116 | Z37: =Y37-X37 -> 46.7
A38: 46034 | B38: PRAIA DO CANTO | C38: 5607.86 | D38: 56 | E38: 23.16 | F38: 1 | G38: 15.33 | H38: 0.2928 | I38: Espirito Santo | K38: PRAIA DO CANTO | L38: 45669 | M38: =L38 -> 45669 | N38: 10527.75 | O38: 11113.35 | P38: 120 | Q38: =O38/P38 -> 92.61125 | R38: 46034 | S38: =R38 -> 46034 | T38: =O39*$AA$1 -> 3870.383 | U38: =C38 -> 5607.86 | V38: =U38/Y38 -> 100.14036 | W38: =U38-T38 -> 1737.477 | X38: =P38*$AA$25 -> 132 | Y38: =D38 -> 56 | Z38: =Y38-X38 -> -76
A39: 46035 | B39: PRAIA DO CANTO | C39: 5871.84 | D39: 61 | E39: 28.03 | F39: 1 | G39: 11 | H39: 0.3402 | I39: Espirito Santo | K39: PRAIA DO CANTO | L39: 45670 | M39: =L39 -> 45670 | N39: 3298.93 | O39: 3518.53 | P39: 44 | Q39: =O39/P39 -> 79.966591 | R39: 46035 | S39: =R39 -> 46035 | T39: =O40*$AA$1 -> 6384.037 | U39: =C39 -> 5871.84 | V39: =U39/Y39 -> 96.259672 | W39: =U39-T39 -> -512.197 | X39: =P39*$AA$25 -> 48.4 | Y39: =D39 -> 61 | Z39: =Y39-X39 -> 12.6
A40: 46036 | B40: PRAIA DO CANTO | C40: 5742.08 | D40: 42 | E40: 24.39 | F40: 0 | G40: 10.5 | H40: 0.2951 | I40: Espirito Santo | K40: PRAIA DO CANTO | L40: 45671 | M40: =L40 -> 45671 | N40: 5559.67 | O40: 5803.67 | P40: 60 | Q40: =O40/P40 -> 96.727833 | R40: 46036 | S40: =R40 -> 46036 | T40: =O41*$AA$1 -> 5399.394 | U40: =C40 -> 5742.08 | V40: =U40/Y40 -> 136.71619 | W40: =U40-T40 -> 342.686 | X40: =P40*$AA$25 -> 66 | Y40: =D40 -> 42 | Z40: =Y40-X40 -> -24
... A50: 46046 | B50: PRAIA DO CANTO | C50: 8461.12 | D50: 81 | E50: 34.53 | F50: 5 | G50: 15.5 | H50: 0.2866 | I50: Espirito Santo | K50: PRAIA DO CANTO | L50: 45681 | M50: =L50 -> 45681 | N50: 7677.8 | O50: 8074.3 | P50: 90 | Q50: =O50/P50 -> 89.714444 | R50: 46046 | S50: =R50 -> 46046 | T50: =O51*$AA$1 -> 9637.716 | U50: =C50 -> 8461.12 | V50: =U50/Y50 -> 104.45827 | W50: =U50-T50 -> -1176.596 | X50: =P50*$AA$25 -> 99 | Y50: =D50 -> 81 | Z50: =Y50-X50 -> -18
A51: 46047 | B51: PRAIA DO CANTO | C51: 9555.52 | D51: 110 | E51: 30.68 | F51: 2 | H51: 0.293 | I51: Espirito Santo | K51: PRAIA DO CANTO | L51: 45682 | M51: =L51 -> 45682 | N51: 8297.96 | O51: 8761.56 | P51: 106 | Q51: =O51/P51 -> 82.656226 | R51: 46047 | S51: =R51 -> 46047 | T51: =O52*$AA$1 -> 10787.26 | U51: =C51 -> 9555.52 | V51: =U51/Y51 -> 86.868364 | W51: =U51-T51 -> -1231.74 | X51: =P51*$AA$25 -> 116.6 | Y51: =D51 -> 110 | Z51: =Y51-X51 -> -6.6
A52: 46048 | B52: PRAIA DO CANTO | C52: 3945.85 | D52: 47 | E52: 23.1 | F52: 0 | G52: 9.66 | H52: 0.2924 | I52: Espirito Santo | K52: PRAIA DO CANTO | L52: 45683 | M52: =L52 -> 45683 | N52: 9251.5 | O52: 9806.6 | P52: 110 | Q52: =O52/P52 -> 89.150909 | R52: 46048 | S52: =R52 -> 46048 | T52: =O53*$AA$1 -> 5095.09 | U52: =C52 -> 3945.85 | V52: =U52/Y52 -> 83.954255 | W52: =U52-T52 -> -1149.24 | X52: =P52*$AA$25 -> 121 | Y52: =D52 -> 47 | Z52: =Y52-X52 -> -74
...

Sheet SPOLETO
B1: OPERAÇÃO | C1: SSS (R$) | D1: SSO (UN) | E1: ADT (MIN) | F1: EXTREMO (UN) | G1: ENTREGAS/MOTOBOY | H1: CMV | I1: LOCALIZAÇÃO | K1: DATA | L1: DIA SEMANA | M1: FATURAMENTO | N1: TC | O1: TM | P1: DATA | Q1: DIA SEMANA | R1: FAT ORÇADO | S1: REALIZADO | T1: TC | U1: DIF | V1: TC ORÇADO | W1: REALIZADO | X1: VAR | Y1: BASE | Z1: 1.15
A2: 45998 | B2: SPOLETO JABAQUARA | C2: 2610.46 | D2: 52 | I2: Sao Paulo
A3: 45999 | B3: SPOLETO JABAQUARA | C3: 3681.65 | D3: 65 | I3: Sao Paulo
A4: 46000 | B4: SPOLETO JABAQUARA | C4: 4372.07 | D4: 79 | I4: Sao Paulo
A5: 46001 | B5: SPOLETO JABAQUARA | C5: 5023.79 | D5: 93 | I5: Sao Paulo
A6: 46002 | B6: SPOLETO JABAQUARA | C6: 5258.9 | D6: 106 | I6: Sao Paulo
A7: 46003 | B7: SPOLETO JABAQUARA | C7: 5350.03 | D7: 110 | I7: Sao Paulo
A8: 46004 | B8: SPOLETO JABAQUARA | C8: 5217.02 | D8: 80 | I8: Sao Paulo
A9: 46005 | B9: SPOLETO JABAQUARA | C9: 3898.58 | D9: 72 | I9: Sao Paulo
A10: 46006 | B10: SPOLETO JABAQUARA | C10: 2999.46 | D10: 61 | I10: Sao Paulo
A11: 46007 | B11: SPOLETO JABAQUARA | C11: 3057.15 | D11: 67 | I11: Sao Paulo
A12: 46008 | B12: SPOLETO JABAQUARA | C12: 4682.58 | D12: 100 | I12: Sao Paulo
A13: 46009 | B13: SPOLETO JABAQUARA | C13: 6142.25 | D13: 125 | I13: Sao Paulo
... A18: 46014 | B18: SPOLETO JABAQUARA | C18: 3698.25 | D18: 76 | I18: Sao Paulo
A19: 46015 | B19: SPOLETO JABAQUARA | I19: Sao Paulo | J19: sem operação
A20: 46016 | B20: SPOLETO JABAQUARA | C20: 3063.45 | D20: 61 | I20: Sao Paulo
A21: 46017 | B21: SPOLETO JABAQUARA | C21: 2821.99 | D21: 53 | I21: Sao Paulo
A22: 46018 | B22: SPOLETO JABAQUARA | C22: 3228.67 | D22: 61 | I22: Sao Paulo
A23: 46019 | B23: SPOLETO JABAQUARA | C23: 2433.08 | D23: 49 | I23: Sao Paulo
A24: 46020 | B24: SPOLETO JABAQUARA | C24: 2707.05 | D24: 56 | I24: Sao Paulo
A25: 46021 | B25: SPOLETO JABAQUARA | C25: 3224.7 | D25: 61 | I25: Sao Paulo
A26: 46022 | B26: SPOLETO JABAQUARA | I26: Sao Paulo | K26: DATA | M26: S/ TX ENTREGA | N26: C/ TX ENTREGA | O26: TC | P26: DATA | R26: FAT ORÇADO | S26: REALIZADO | T26: TM | U26: DIF | V26: TC ORÇADO | W26: REALIZADO | X26: VAR | Y26: BASE | Z26: 1.1
A27: 46023 | B27: SPOLETO JABAQUARA | C27: 343.9 | D27: 6 | I27: Sao Paulo | K27: 45658 | L27: =K27 -> 45658 | M27: 3385.02 | N27: 72 | O27: 47.01 | P27: 46023 | Q27: =P27 -> 46023 | R27: =M27*$Z$1 -> 3892.773 | S27: =C27 -> 343.9 | T27: =S27/V27 -> 4.1533816 | U27: =R27-T27 -> 3888.6196 | V27: =N27*$Z$1 -> 82.8 | W27: =D27 -> 6 | X27: =W27-V27 -> -76.8
A28: 46024 | B28: SPOLETO JABAQUARA | C28: 2743.5 | D28: 65 | I28: Sao Paulo | K28: 45659 | L28: =K28 -> 45659 | M28: 3385.02 | N28: 72 | O28: 47.01 | P28: 46024 | Q28: =P28 -> 46024 | R28: =M28*$Z$1 -> 3892.773 | S28: =C28 -> 2743.5 | T28: =S28/V28 -> 33.134058 | U28: =R28-T28 -> 3859.6389 | V28: =N28*$Z$1 -> 82.8 | W28: =D28 -> 65 | X28: =W28-V28 -> -17.8
A29: 46025 | B29: SPOLETO JABAQUARA | I29: Sao Paulo | K29: 45660 | L29: =K29 -> 45660 | M29: 3385.02 | N29: 72 | O29: 47.01 | P29: 46025 | Q29: =P29 -> 46025 | R29: =M29*$Z$1 -> 3892.773 | S29: 0 | T29: =S29/V29 -> 0 | U29: =R29-T29 -> 3892.773 | V29: =N29*$Z$1 -> 82.8 | W29: 0 | X29: =W29-V29 -> -82.8
A30: 46026 | B30: SPOLETO JABAQUARA | C30: 2315.45 | D30: 45 | I30: Sao Paulo | K30: 45661 | L30: =K30 -> 45661 | M30: 3385.02 | N30: 72 | O30: 47.01 | P30: 46026 | Q30: =P30 -> 46026 | R30: =M30*$Z$1 -> 3892.773 | S30: =C30 -> 2315.45 | T30: =S30/V30 -> 27.964372 | U30: =R30-T30 -> 3864.8086 | V30: =N30*$Z$1 -> 82.8 | W30: =D30 -> 45 | X30: =W30-V30 -> -37.8
A31: 46027 | B31: SPOLETO JABAQUARA | C31: 3057.65 | D31: 64 | I31: Sao Paulo | K31: 45662 | L31: =K31 -> 45662 | M31: 3385.02 | N31: 72 | O31: 47.01 | P31: 46027 | Q31: =P31 -> 46027 | R31: =M31*$Z$1 -> 3892.773 | S31: =C31 -> 3057.65 | T31: =S31/V31 -> 36.92814 | U31: =R31-T31 -> 3855.8449 | V31: =N31*$Z$1 -> 82.8 | W31: =D31 -> 64 | X31: =W31-V31 -> -18.8
A32: 46028 | B32: SPOLETO JABAQUARA | C32: 3385.8 | D32: 60 | I32: Sao Paulo | K32: 45663 | L32: =K32 -> 45663 | M32: 3385.02 | N32: 72 | O32: 47.01 | P32: 46028 | Q32: =P32 -> 46028 | R32: =M32*$Z$1 -> 3892.773 | S32: =C32 -> 3385.8 | T32: =S32/V32 -> 40.891304 | U32: =R32-T32 -> 3851.8817 | V32: =N32*$Z$1 -> 82.8 | W32: =D32 -> 60 | X32: =W32-V32 -> -22.8
A33: 46029 | B33: SPOLETO JABAQUARA | C33: 3467.6 | D33: 71 | I33: Sao Paulo | K33: 45664 | L33: =K33 -> 45664 | M33: 3385.02 | N33: 72 | O33: 47.01 | P33: 46029 | Q33: =P33 -> 46029 | R33: =M33*$Z$1 -> 3892.773 | S33: =C33 -> 3467.6 | T33: =S33/V33 -> 41.879227 | U33: =R33-T33 -> 3850.8938 | V33: =N33*$Z$1 -> 82.8 | W33: =D33 -> 71 | X33: =W33-V33 -> -11.8
A34: 46030 | B34: SPOLETO JABAQUARA | C34: 3977.2 | D34: 82 | I34: Sao Paulo | K34: 45665 | L34: =K34 -> 45665 | M34: 3385.02 | N34: 72 | O34: 47.01 | P34: 46030 | Q34: =P34 -> 46030 | R34: =M34*$Z$1 -> 3892.773 | S34: =C34 -> 3977.2 | T34: =S34/V34 -> 48.033816 | U34: =R34-T34 -> 3844.7392 | V34: =N34*$Z$1 -> 82.8 | W34: =D34 -> 82 | X34: =W34-V34 -> -0.8
A35: 46031 | B35: SPOLETO JABAQUARA | C35: 6399.6 | D35: 73 | I35: Sao Paulo | K35: 45666 | L35: =K35 -> 45666 | M35: 3385.02 | N35: 72 | O35: 47.01 | P35: 46031 | Q35: =P35 -> 46031 | R35: =M35*$Z$1 -> 3892.773 | S35: =C35 -> 6399.6 | T35: =S35/V35 -> 77.289855 | U35: =R35-T35 -> 3815.4831 | V35: =N35*$Z$1 -> 82.8 | W35: =D35 -> 73 | X35: =W35-V35 -> -9.8
A36: 46032 | B36: SPOLETO JABAQUARA | C36: 3646.2 | D36: 76 | I36: Sao Paulo | K36: 45667 | L36: =K36 -> 45667 | M36: 3385.02 | N36: 72 | O36: 47.01 | P36: 46032 | Q36: =P36 -> 46032 | R36: =M36*$Z$1 -> 3892.773 | S36: =C36 -> 3646.2 | T36: =S36/V36 -> 44.036232 | U36: =R36-T36 -> 3848.7368 | V36: =N36*$Z$1 -> 82.8 | W36: =D36 -> 76 | X36: =W36-V36 -> -6.8
A37: 46033 | B37: SPOLETO JABAQUARA | C37: 1443.85 | D37: 28 | I37: Sao Paulo | K37: 45668 | L37: =K37 -> 45668 | M37: 3385.02 | N37: 72 | O37: 47.01 | P37: 46033 | Q37: =P37 -> 46033 | R37: =M37*$Z$1 -> 3892.773 | S37: =C37 -> 1443.85 | T37: =S37/V37 -> 17.437802 | U37: =R37-T37 -> 3875.3352 | V37: =N37*$Z$1 -> 82.8 | W37: =D37 -> 28 | X37: =W37-V37 -> -54.8
A38: 46034 | B38: SPOLETO JABAQUARA | C38: 3394.4 | D38: 70 | I38: Sao Paulo | K38: 45669 | L38: =K38 -> 45669 | M38: 3385.02 | N38: 72 | O38: 47.01 | P38: 46034 | Q38: =P38 -> 46034 | R38: =M38*$Z$1 -> 3892.773 | S38: =C38 -> 3394.4 | T38: =S38/V38 -> 40.995169 | U38: =R38-T38 -> 3851.7778 | V38: =N38*$Z$1 -> 82.8 | W38: =D38 -> 70 | X38: =W38-V38 -> -12.8
A39: 46035 | B39: SPOLETO JABAQUARA | C39: 2705.4 | D39: 56 | I39: Sao Paulo | K39: 45670 | L39: =K39 -> 45670 | M39: 3385.02 | N39: 72 | O39: 47.01 | P39: 46035 | Q39: =P39 -> 46035 | R39: =M39*$Z$1 -> 3892.773 | S39: =C39 -> 2705.4 | T39: =S39/V39 -> 32.673913 | U39: =R39-T39 -> 3860.0991 | V39: =N39*$Z$1 -> 82.8 | W39: =D39 -> 56 | X39: =W39-V39 -> -26.8
A40: 46036 | B40: SPOLETO JABAQUARA | C40: 2513.25 | D40: 50 | I40: Sao Paulo | K40: 45671 | L40: =K40 -> 45671 | M40: 3385.02 | N40: 72 | O40: 47.01 | P40: 46036 | Q40: =P40 -> 46036 | R40: =M40*$Z$1 -> 3892.773 | S40: =C40 -> 2513.25 | T40: =S40/V40 -> 30.353261 | U40: =R40-T40 -> 3862.4197 | V40: =N40*$Z$1 -> 82.8 | W40: =D40 -> 50 | X40: =W40-V40 -> -32.8
A41: 46037 | B41: SPOLETO JABAQUARA | C41: 2836.65 | D41: 59 | I41: Sao Paulo | K41: 45672 | L41: =K41 -> 45672 | M41: 3385.02 | N41: 72 | O41: 47.01 | P41: 46037 | Q41: =P41 -> 46037 | R41: =M41*$Z$1 -> 3892.773 | S41: =C41 -> 2836.65 | T41: =S41/V41 -> 34.259058 | U41: =R41-T41 -> 3858.5139 | V41: =N41*$Z$1 -> 82.8 | W41: =D41 -> 59 | X41: =W41-V41 -> -23.8
... A57: 46053 | B57: SPOLETO JABAQUARA | C57: 2320.5 | D57: 47 | I57: Sao Paulo | K57: 45688 | L57: =K57 -> 45688 | M57: 3385.02 | N57: 72 | O57: 47.01 | P57: 46053 | Q57: =P57 -> 46053 | R57: =M57*$Z$1 -> 3892.773 | S57: =C57 -> 2320.5 | T57: =S57/V57 -> 28.025362 | U57: =R57-T57 -> 3864.7476 | V57: =N57*$Z$1 -> 82.8 | W57: =D57 -> 47 | X57: =W57-V57 -> -35.8
A58: 46054 | B58: SPOLETO JABAQUARA | C58: 2324.04 | D58: 50 | I58: Sao Paulo | K58: 46047 | L58: =K58 -> 46047 | M58: =SUM(M2:M57) -> 104935.62 | N58: =SUM(N2:N57) -> 2232 | O58: =MEDIAN(O2:O57) -> 47.01 | P58: 46048 | Q58: TOTAL | R58: =SUM(R27:R57) -> 120675.96 | S58: =SUM(S27:S57) -> 94673.17 | T58: =S58/W58 -> 49.933107 | U58: =R58-S58 -> 26002.793 | V58: =N58*$Z$1 -> 2566.8 | W58: =SUM(W2:W57) -> 1896 | X58: =W58-V58 -> -670.8
A59: 46055 | B59: SPOLETO JABAQUARA | C59: 3516.75 | D59: 72 | I59: Sao Paulo | K59: 45689 | L59: =K59 -> 45689 | M59: 3385.02 | N59: 72 | O59: 47.01 | P59: 46054 | Q59: =P59 -> 46054 | R59: =M59*$Z$1 -> 3892.773 | S59: =C58 -> 2324.04 | T59: =S59/V59 -> 28.068116 | U59: =R59-T59 -> 3864.7049 | V59: =N59*$Z$1 -> 82.8 | W59: =D59 -> 72 | X59: =W59-V59 -> -10.8
...

Sheet PINHEIROS
A1: 0 | B1: OPERAÇÃO | C1: SSS (R$) | D1: SSO (UN) | E1: ADT (MIN) | F1: EXTREMO (UN) | G1: ENTREGAS/MOTOBOY | H1: CMV | I1: LOCALIZAÇÃO | J1: OBS | K1: NOME | L1: DATA | M1: DIA SEMANA | N1: S/ TX ENTREGA | O1: C/ TX ENTREGA | P1: TC | Q1: TM | R1: DATA | S1: DIA SEMANA | T1: FAT ORÇADO | U1: REALIZADO | V1: TM | W1: DIF | X1: TC ORÇADO | Y1: REALIZADO | Z1: VAR | AA1: 1.1 | AB1: BASE
A2: 45998 | B2: PINHEIROS | C2: =6127.62+416.5 -> 6544.12 | D2: 60 | E2: 41.8 | F2: 10 | G2: 15 | H2: 0.319 | I2: Sao Paulo
A3: 45999 | B3: PINHEIROS | C3: 3206.9 | D3: 34 | E3: 21.58 | F3: 1 | G3: 9.67 | H3: 0.334 | I3: Sao Paulo
A4: 46000 | B4: PINHEIROS | C4: 3469.53 | D4: 40 | E4: 51.03 | F4: 17 | G4: 16.5 | H4: 0.3254 | I4: Sao Paulo | J4: queda de luz e falta de motoboy
A5: 46001 | B5: PINHEIROS | C5: 4420.16 | D5: 36 | E5: 28.25 | F5: 3 | G5: 12 | H5: 0.3212 | I5: Sao Paulo | J5: turno da noite, tambem trabalhou com sob de manda
A6: 46002 | B6: PINHEIROS | C6: 4085.95 | D6: 34 | E6: 25.53 | F6: 3 | G6: 16 | H6: 0.3217 | I6: Sao Paulo | J6: trabalhou apenas um motooby, noite rodoou com sob demanda
A7: 46003 | B7: PINHEIROS | C7: 8335.39 | D7: 84 | E7: 40.43 | F7: 4 | G7: 13.9 | H7: 0.3373 | I7: Sao Paulo
A8: 46004 | B8: PINHEIROS | C8: 6978.95 | D8: 83 | E8: 31.17 | F8: 5 | G8: 13.25 | H8: 0.3014 | I8: Sao Paulo
A9: 46005 | B9: PINHEIROS | C9: 4529 | D9: 46 | E9: 34.56 | F9: 4 | G9: 11.33 | H9: 0.2898 | I9: Sao Paulo
A10: 46006 | B10: PINHEIROS | C10: 1846.91 | D10: 16 | E10: 25.76 | F10: 0 | G10: 5.33 | H10: 0.3149 | I10: Sao Paulo
A11: 46007 | B11: PINHEIROS | C11: 4717.77 | D11: 41 | E11: 37.21 | F11: 19 | G11: 7 | H11: 0.3409 | I11: Sao Paulo
A12: 46008 | B12: PINHEIROS | C12: 7506.28 | D12: 43 | E12: 52.52 | F12: 7 | G12: 7 | H12: 0.3243 | I12: Sao Paulo | J12: tempo de adt alto por conta de dois pedidos que ficou alto
A13: 46009 | B13: PINHEIROS | C13: 7062.47 | D13: 59 | E13: 28.38 | F13: 4 | G13: 17 | H13: 0.3162 | I13: Sao Paulo
A14: 46010 | B14: PINHEIROS | C14: 8908.14 | D14: 80 | E14: 31.18 | F14: 13 | G14: 10.5 | H14: 0.2945 | I14: Sao Paulo
A15: 46011 | B15: PINHEIROS | C15: 8835.84 | D15: 97 | E15: 29.92 | F15: 7 | G15: 11.16 | H15: 0.3745 | I15: Sao Paulo
A16: 46012 | B16: PINHEIROS | C16: 6180.17 | D16: 58 | E16: 38.49 | F16: 7 | G16: 9.6 | H16: 0.3152 | I16: Sao Paulo
A17: 46013 | B17: PINHEIROS | C17: 3542.56 | D17: 25 | E17: 38.49 | F17: 7 | G17: 7 | H17: 0.311 | I17: Sao Paulo
A18: 46014 | B18: PINHEIROS | C18: 5193.93 | D18: 49 | E18: 25.82 | F18: 4 | G18: 8.2 | H18: 0.3624 | I18: Sao Paulo
A19: 46015 | B19: PINHEIROS | I19: Sao Paulo | J19: loja fechada
A20: 46016 | B20: PINHEIROS | C20: 10063 | D20: 105 | E20: 32.63 | F20: 13 | G20: 12.57 | H20: 0.3334 | I20: Sao Paulo
A21: 46017 | B21: PINHEIROS | C21: 4247.1 | D21: 56 | E21: 30.29 | F21: 8 | G21: 8.6 | H21: 0.2688 | I21: Sao Paulo
A22: 46018 | B22: PINHEIROS | C22: 5275.9 | D22: 62 | E22: 29.12 | F22: 10 | G22: 7.6 | H22: 0.3826 | I22: Sao Paulo
A23: 46019 | B23: PINHEIROS | C23: 3916.5 | D23: 36 | E23: 29.39 | F23: 4 | G23: 8 | H23: 0.3076 | I23: Sao Paulo
A24: 46020 | B24: PINHEIROS | C24: 3122.66 | D24: 37 | E24: 30.25 | F24: 6 | G24: 13 | H24: 0.3356 | I24: Sao Paulo
A25: 46021 | B25: PINHEIROS | C25: 3426.7 | D25: 36 | E25: 28.71 | F25: 4 | G25: 6.4 | H25: 0.3108 | I25: Sao Paulo
A26: 46022 | B26: PINHEIROS | I26: Sao Paulo | J26: fechada | K26: NOME | L26: DATA | M26: DIA SEMANA | N26: S/ TX ENTREGA | O26: C/ TX ENTREGA | P26: TC | Q26: TM | R26: DATA | S26: DIA SEMANA | T26: FAT ORÇADO | U26: REALIZADO | V26: TM | W26: DIF | X26: TC ORÇADO | Y26: REALIZADO | Z26: VAR
A27: 46023 | B27: PINHEIROS | C27: 7134.49 | D27: 79 | E27: 39.23 | F27: 13 | G27: 13.8 | H27: 0.3001 | I27: Sao Paulo | K27: PINHEIROS | L27: 45658 | M27: 45658 | N27: 5102.51 | O27: 5102.51 | P27: 60 | Q27: 85.04 | R27: 46023 | S27: 46023 | T27: =O28*$AA$1 -> 2047.012 | U27: =C27 -> 7134.49 | V27: =U27/Y27 -> 90.31 | W27: =U27-T27 -> 5087.478 | X27: =P27*$AA$1 -> 66 | Y27: =D27 -> 79 | Z27: =Y27-X27 -> 13
A28: 46024 | B28: PINHEIROS | C28: 4156.08 | D28: 41 | E28: 30.03 | F28: 8 | G28: 11.33 | H28: 0.2723 | I28: Sao Paulo | K28: PINHEIROS | L28: 45659 | M28: 45659 | N28: 1759.73 | O28: 1860.92 | P28: 23 | Q28: 80.91 | R28: 46024 | S28: 46024 | T28: =O29*$AA$1 -> 3623.048 | U28: =C28 -> 4156.08 | V28: =U28/Y28 -> 101.3678 | W28: =U28-T28 -> 533.032 | X28: =P28*$AA$1 -> 25.3 | Y28: =D28 -> 41 | Z28: =Y28-X28 -> 15.7
A29: 46025 | B29: PINHEIROS | C29: 6844.99 | D29: 75 | E29: 28.47 | F29: 7 | G29: 14.5 | H29: 0.2631 | I29: Sao Paulo | K29: PINHEIROS | L29: 45660 | M29: 45660 | N29: 2824.64 | O29: 3293.68 | P29: 40 | Q29: 82.34 | R29: 46025 | S29: 46025 | T29: =O30*$AA$1 -> 4436.465 | U29: =C29 -> 6844.99 | V29: =U29/Y29 -> 91.266533 | W29: =U29-T29 -> 2408.525 | X29: =P29*$AA$1 -> 44 | Y29: =D29 -> 75 | Z29: =Y29-X29 -> 31
A30: 46026 | B30: PINHEIROS | C30: =5912+476 -> 6388 | D30: 59 | E30: 30.79 | F30: 11 | G30: 9.6 | H30: 0.3137 | I30: Sao Paulo | K30: PINHEIROS | L30: 45661 | M30: 45661 | N30: 3732.38 | O30: 4033.15 | P30: 46 | Q30: 87.68 | R30: 46026 | S30: 46026 | T30: =O31*$AA$1 -> 3518.119 | U30: =C30 -> 6388 | V30: =U30/Y30 -> 108.27119 | W30: =U30-T30 -> 2869.881 | X30: =P30*$AA$1 -> 50.6 | Y30: =D30 -> 59 | Z30: =Y30-X30 -> 8.4
A31: 46027 | B31: PINHEIROS | C31: 2397.3 | D31: 23 | E31: 28.42 | F31: 4 | G31: 11 | H31: 0.3681 | I31: Sao Paulo | K31: PINHEIROS | L31: 45662 | M31: 45662 | N31: 2959.77 | O31: 3198.29 | P31: 35 | Q31: 91.38 | R31: 46027 | S31: 46027 | T31: =O32*$AA$1 -> 1863.51 | U31: =C31 -> 2397.3 | V31: =U31/Y31 -> 104.23043 | W31: =U31-T31 -> 533.79 | X31: =P31*$AA$1 -> 38.5 | Y31: =D31 -> 23 | Z31: =Y31-X31 -> -15.5
A32: 46028 | B32: PINHEIROS | C32: 3330.43 | D32: 28 | E32: 26.45 | F32: 2 | G32: 5.75 | H32: 0.3295 | I32: Sao Paulo | K32: PINHEIROS | L32: 45663 | M32: 45663 | N32: 1578.45 | O32: 1694.1 | P32: 19 | Q32: 89.16 | R32: 46028 | S32: 46028 | T32: =O33*$AA$1 -> 2652.364 | U32: =C32 -> 3330.43 | V32: =U32/Y32 -> 118.94393 | W32: =U32-T32 -> 678.066 | X32: =P32*$AA$1 -> 20.9 | Y32: =D32 -> 28 | Z32: =Y32-X32 -> 7.1
A33: 46029 | B33: PINHEIROS | C33: 2672.14 | D33: 27 | E33: 24.61 | F33: 0 | G33: 5.75 | H33: 0.3032 | I33: Sao Paulo | K33: PINHEIROS | L33: 45664 | M33: 45664 | N33: 2259.45 | O33: 2411.24 | P33: 25 | Q33: 96.45 | R33: 46029 | S33: 46029 | T33: =O34*$AA$1 -> 3951.651 | U33: =C33 -> 2672.14 | V33: =U33/Y33 -> 98.968148 | W33: =U33-T33 -> -1279.511 | X33: =P33*$AA$1 -> 27.5 | Y33: =D33 -> 27 | Z33: =Y33-X33 -> -0.5
A34: 46030 | B34: PINHEIROS | C34: 3391.58 | D34: 39 | E34: 23.4 | F34: 0 | G34: 7 | H34: 0.2761 | I34: Sao Paulo | K34: PINHEIROS | L34: 45665 | M34: 45665 | N34: 3397.25 | O34: 3592.41 | P34: 45 | Q34: 79.83 | R34: 46030 | S34: 46030 | T34: =O35*$AA$1 -> 2205.28 | U34: =C34 -> 3391.58 | V34: =U34/Y34 -> 86.96359 | W34: =U34-T34 -> 1186.3 | X34: =P34*$AA$1 -> 49.5 | Y34: =D34 -> 39 | Z34: =Y34-X34 -> -10.5
A35: 46031 | B35: PINHEIROS | C35: 5983.22 | D35: 65 | E35: 25.97 | F35: 3 | G35: 7.33 | H35: 0.2707 | I35: Sao Paulo | K35: PINHEIROS | L35: 45666 | M35: 45666 | N35: 1860.24 | O35: 2004.8 | P35: 21 | Q35: 95.47 | R35: 46031 | S35: 46031 | T35: =O36*$AA$1 -> 4765.013 | U35: =C35 -> 5983.22 | V35: =U35/Y35 -> 92.049538 | W35: =U35-T35 -> 1218.207 | X35: =P35*$AA$1 -> 23.1 | Y35: =D35 -> 65 | Z35: =Y35-X35 -> 41.9
A36: 46032 | B36: PINHEIROS | C36: 5247.69 | D36: 67 | E36: 25.36 | F36: 1 | G36: 5.83 | H36: 0.2433 | I36: Sao Paulo | K36: PINHEIROS | L36: 45667 | M36: 45667 | N36: 4136.67 | O36: 4331.83 | P36: 45 | Q36: 96.26 | R36: 46032 | S36: 46032 | T36: =O37*$AA$1 -> 6303.704 | U36: =C36 -> 5247.69 | V36: =U36/Y36 -> 78.323731 | W36: =U36-T36 -> -1056.014 | X36: =P36*$AA$1 -> 49.5 | Y36: =D36 -> 67 | Z36: =Y36-X36 -> 17.5
A37: 46033 | B37: PINHEIROS | C37: 3953.47 | D37: 43 | E37: 27.43 | F37: 1 | G37: 11.66 | H37: 0.2954 | I37: Sao Paulo | K37: PINHEIROS | L37: 45668 | M37: 45668 | N37: 5419.84 | O37: 5730.64 | P37: 59 | Q37: 97.13 | R37: 46033 | S37: 46033 | T37: =O38*$AA$1 -> 3167.197 | U37: =C37 -> 3953.47 | V37: =U37/Y37 -> 91.941163 | W37: =U37-T37 -> 786.273 | X37: =P37*$AA$1 -> 64.9 | Y37: =D37 -> 43 | Z37: =Y37-X37 -> -21.9
A38: 46034 | B38: PINHEIROS | C38: 2814.4 | D38: 28 | E38: 25.76 | F38: 0 | G38: 13 | H38: 0.2907 | I38: Sao Paulo | K38: PINHEIROS | L38: 45669 | M38: 45669 | N38: 2705.8 | O38: 2879.27 | P38: 32 | Q38: 89.98 | R38: 46034 | S38: 46034 | T38: =O39*$AA$1 -> 1834.789 | U38: =C38 -> 2814.4 | V38: =U38/Y38 -> 100.51429 | W38: =U38-T38 -> 979.611 | X38: =P38*$AA$1 -> 35.2 | Y38: =D38 -> 28 | Z38: =Y38-X38 -> -7.2
A39: 46035 | B39: PINHEIROS | C39: 5488.5 | D39: 35 | E39: 25.79 | F39: 2 | G39: 7.25 | H39: 0.2892 | I39: Sao Paulo | K39: PINHEIROS | L39: 45670 | M39: 45670 | N39: 1566.8 | O39: 1667.99 | P39: 18 | Q39: 92.67 | R39: 46035 | S39: 46035 | T39: =O40*$AA$1 -> 2540.142 | U39: =C39 -> 5488.5 | V39: =U39/Y39 -> 156.81429 | W39: =U39-T39 -> 2948.358 | X39: =P39*$AA$1 -> 19.8 | Y39: =D39 -> 35 | Z39: =Y39-X39 -> 15.2
A40: 46036 | B40: PINHEIROS | C40: 3335.96 | D40: 33 | E40: 24.47 | F40: 2 | G40: 13.5 | H40: 0.263 | I40: Sao Paulo | K40: PINHEIROS | L40: 45671 | M40: 45671 | N40: 2164.66 | O40: 2309.22 | P40: 26 | Q40: 88.82 | R40: 46036 | S40: 46036 | T40: =O41*$AA$1 -> 2560.602 | U40: =C40 -> 3335.96 | V40: =U40/Y40 -> 101.0897 | W40: =U40-T40 -> 775.358 | X40: =P40*$AA$1 -> 28.6 | Y40: =D40 -> 33 | Z40: =Y40-X40 -> 4.4
...

Sheet Página21

Sheet AEROPORTO
A1: DATA | B1: OPERAÇÃO | C1: SSS (R$) | D1: SSO (UN) | E1: ADT (MIN) | F1: EXTREMO (UN) | G1: ENTREGAS/MOTOBOY | H1: CMV | I1: LOCALIZAÇÃO | J1: OBS | K1: LOJA | L1: DATA | M1: DIA SEMANA | N1: FATURAMENTO | O1: TC | P1: DATA | Q1: DIA SEMANA | R1: TM | S1: FAT ORÇADO | T1: REALIZADO | U1: TM | V1: GAP | W1: TC ORÇADO | X1: REALIZADO | Y1: VAR | Z1: 1.2 | AA1: 1.1
A2: 45998 | B2: AEROPORTO GRU | C2: 9990.5 | D2: 142 | I2: Sao Paulo
A3: 45999 | B3: AEROPORTO GRU | C3: 11851.75 | D3: 174 | I3: Sao Paulo
A4: 46000 | B4: AEROPORTO GRU | C4: 9523 | D4: 147 | I4: Sao Paulo
A5: 46001 | B5: AEROPORTO GRU | C5: 7372.25 | D5: 119 | I5: Sao Paulo
A6: 46002 | B6: AEROPORTO GRU | C6: 9333.9 | D6: 141 | I6: Sao Paulo
A7: 46003 | B7: AEROPORTO GRU | C7: 9177.25 | D7: 152 | I7: Sao Paulo
A8: 46004 | B8: AEROPORTO GRU | C8: 8731.5 | D8: 134 | I8: Sao Paulo
A9: 46005 | B9: AEROPORTO GRU | C9: 9782.75 | D9: 131 | I9: Sao Paulo
A10: 46006 | B10: AEROPORTO GRU | C10: 9544.75 | D10: 147 | I10: Sao Paulo
A11: 46007 | B11: AEROPORTO GRU | C11: 10752.5 | D11: 176 | I11: Sao Paulo
A12: 46008 | B12: AEROPORTO GRU | C12: 6946.75 | D12: 113 | I12: Sao Paulo
A13: 46009 | B13: AEROPORTO GRU | C13: 9577.5 | D13: 151 | I13: Sao Paulo
... A25: 46021 | B25: AEROPORTO GRU | C25: 11869 | D25: 166 | I25: Sao Paulo
A26: 46022 | B26: AEROPORTO GRU | C26: 6837.5 | D26: 101 | I26: Sao Paulo | K26: UNIDADE | L26: DATA | N26: FAT | O26: TC | P26: DATA | R26: TM | S26: FAT ORÇADO | T26: REALIZADO | U26: TM | V26: GAP | W26: TC ORÇADO | X26: REALIZADO | Y26: VAR | AA26: BASE | AB26: 1.1
A27: 46023 | B27: AEROPORTO GRU | C27: 7677.75 | D27: 104 | I27: Sao Paulo | K27: AEROPORTO GUARULHOS | L27: 45658 | M27: =L27 -> 45658 | N27: 8793.89 | O27: 146 | P27: =A27 -> 46023 | Q27: =P27 -> 46023 | R27: =N27/O27 -> 60.232123 | S27: =N28*$Z$1 -> 10552.668 | T27: =C27 -> 7677.75 | U27: =T27/X27 -> 73.824519 | V27: =T27-S27 -> -2874.918 | W27: =O27*$Z$1 -> 175.2 | X27: =D27 -> 104 | Y27: =X27-W27 -> -71.2
A28: 46024 | B28: AEROPORTO GRU | C28: 7949.75 | D28: 116 | I28: Sao Paulo | K28: AEROPORTO GUARULHOS | L28: 45659 | M28: =L28 -> 45659 | N28: 8793.89 | O28: 146 | P28: =A28 -> 46024 | Q28: =P28 -> 46024 | R28: =N28/O28 -> 60.232123 | S28: =N29*$Z$1 -> 10552.668 | T28: =C28 -> 7949.75 | U28: =T28/X28 -> 68.532328 | V28: =T28-S28 -> -2602.918 | W28: =O28*$Z$1 -> 175.2 | X28: =D28 -> 116 | Y28: =X28-W28 -> -59.2
